<?xml version="1.0"?>
<robot name="spyndra" xmlns:xacro="http://www.ros.org/wiki/xacro">
  <!-- constants -->
  <xacro:property name="pi" value="3.1415926535897931"/>

  <!-- link offset for each STL file -->
  <xacro:property name="off_cx" value="-0.11" />
  <xacro:property name="off_cy" value="-0.068" />
  <xacro:property name="off_cz" value="0" />
  <xacro:property name="off_fx" value="-0.00825" />
  <xacro:property name="off_fy" value="0.0455" />
  <xacro:property name="off_fz" value="-0.022" />
  <xacro:property name="off_tx" value="0.1735" />
  <xacro:property name="off_ty" value="0.0215" />
  <xacro:property name="off_tz" value="-0.02" />

  <!-- joint position -->
  <xacro:property name="jt_cx" value="0.0585" />
  <xacro:property name="jt_cy" value="-0.003" />
  <xacro:property name="jt_cz" value="0.047" />
  <xacro:property name="jt_fx" value="0.111" />
  <xacro:property name="jt_fy" value="0.003" />
  <xacro:property name="jt_fz" value="0" />

  <!-- component mass -->
  <xacro:property name="mc" value="0.23069271"/>
  <xacro:property name="mf" value="0.20096365"/>
  <xacro:property name="mt" value="0.10764861"/>

  <!-- TODO: center of mass -->
  <xacro:property name="chassis_origin_z" value="0.09441"/>
  <xacro:property name="femur_origin_x" value="0.0635"/>
  <xacro:property name="tibia_origin_x" value="0.09429"/>
  <xacro:property name="femur_origin_z" value="0.09441"/>

  <!-- moment of inertia -->
  <xacro:property name="chassis_ixx" value="0.0029636" />
  <xacro:property name="chassis_ixy" value="0.00000019" />
  <xacro:property name="chassis_iyy" value="0.00028197" />
  <xacro:property name="chassis_iyz" value="-0.00000269" />
  <xacro:property name="chassis_izz" value="0.00044786" />
  <xacro:property name="chassis_ixz" value="-0.00000106" />

  <xacro:property name="femur_ixx" value="0.00025261" />
  <xacro:property name="femur_ixy" value="0.0" />
  <xacro:property name="femur_iyy" value="0.00014944" />
  <xacro:property name="femur_iyz" value="-0.00000002" />
  <xacro:property name="femur_izz" value="0.00013756" />
  <xacro:property name="femur_ixz" value="-0.00000601" />

  <xacro:property name="tibia_ixx" value="0.00021435" />
  <xacro:property name="tibia_ixy" value="-0.00000128" />
  <xacro:property name="tibia_iyy" value="0.00019560" />
  <xacro:property name="tibia_iyz" value="-0.00005856" />
  <xacro:property name="tibia_izz" value="0.00004159" />
  <xacro:property name="tibia_ixz" value="0.00000606" />

  <!-- Import all Gazebo-customization elements -->
  <xacro:include filename="$(find spyndra_description)/urdf/spyndra.gazebo" />
  <xacro:include filename="$(find spyndra_description)/urdf/materials.xacro" />

  <!-- links -->
  <link name="base_link">
    <collision>
      <geometry>
        <mesh filename="package://spyndra_description/meshes/chassis.stl"     scale="0.001 0.001 0.001"/>
      </geometry>
      <origin xyz="${off_cx} ${off_cy} ${off_cz}" rpy="0 0 0"/>
    </collision>
    <visual>
      <geometry>
        <mesh filename="package://spyndra_description/meshes/chassis.stl"     scale="0.001 0.001 0.001"/>
      </geometry>
      <origin xyz="${off_cx} ${off_cy} ${off_cz}" rpy="0 0 0"/>
      <material name="black"/>
    </visual>
    <inertial>
      <origin xyz="0 0 ${chassis_origin_z}"  rpy="0 0 0"/>
      <mass value="${mc}"/>
      <inertia ixx="${chassis_ixx}" ixy="${chassis_ixy}"
        iyy="${chassis_iyy}" iyz = "${chassis_iyz}"
        izz="${chassis_izz}" ixz="${chassis_ixz}" />
    </inertial>
  </link>

  <link name="femur_1">
    <collision>
      <geometry>
        <mesh filename="package://spyndra_description/meshes/femur.stl" scale="0.001 0.001 0.001"/>
      </geometry>
      <material name="red"/>
      <origin xyz="${off_fx} ${off_fy} ${off_fz}" rpy="${pi} ${-pi/2} 0"/>
    </collision>
    <visual>
      <geometry>
        <mesh filename="package://spyndra_description/meshes/femur.stl" scale="0.001 0.001 0.001"/>
      </geometry>
      <material name="red"/>
      <origin xyz="${off_fx} ${off_fy} ${off_fz}" rpy="${pi} ${-pi/2} 0"/>
    </visual>
    <inertial>
      <origin xyz="${femur_origin_x} 0 ${femur_origin_z}" rpy="0 0 0"/>
      <mass value="${mf}"/>
      <inertia ixx="${femur_ixx}" ixy="${femur_ixy}"
        iyy="${femur_iyy}" iyz = "${femur_iyz}"
        izz="${femur_izz}" ixz="${femur_ixz}" />
    </inertial>
  </link>

  <link name="tibia_1">
    <collision>
      <geometry>
        <mesh filename="package://spyndra_description/meshes/tibia.stl" scale="0.001 0.001 0.001"/>
      </geometry>
      <material name="white"/>
      <origin xyz="${off_tx} ${off_ty} ${off_tz}" rpy="${pi/2} 0 ${-pi/2}"/>
    </collision>
    <visual>
      <geometry>
        <mesh filename="package://spyndra_description/meshes/tibia.stl" scale="0.001 0.001 0.001"/>
      </geometry>
      <material name="white"/>
      <origin xyz="${off_tx} ${off_ty} ${off_tz}" rpy="${pi/2} 0 ${-pi/2}"/>
    </visual>
    <inertial>
      <origin xyz="${tibia_origin_x} 0 0" rpy="0 0 0"/>
      <mass value="${mt}"/>
      <inertia ixx="${tibia_ixx}" ixy="${tibia_ixy}"
        iyy="${tibia_iyy}" iyz = "${tibia_iyz}"
        izz="${tibia_izz}" ixz="${tibia_ixz}" />
    </inertial>
  </link>

  <link name="femur_2">
    <collision>
      <geometry>
        <mesh filename="package://spyndra_description/meshes/femur.stl" scale="0.001 0.001 0.001"/>
      </geometry>
      <material name="red"/>
      <origin xyz="${off_fx} ${off_fy} ${off_fz}" rpy="${pi} ${-pi/2} 0"/>
    </collision>
    <visual>
      <geometry>
        <mesh filename="package://spyndra_description/meshes/femur.stl" scale="0.001 0.001 0.001"/>
      </geometry>
      <material name="red"/>
      <origin xyz="${off_fx} ${off_fy} ${off_fz}" rpy="${pi} ${-pi/2} 0"/>
    </visual>
    <inertial>
      <origin xyz="${femur_origin_x} 0 ${femur_origin_z}"  rpy="0 0 0"/>
      <mass value="${mc}"/>
      <inertia ixx="${femur_ixx}" ixy="${femur_ixy}"
        iyy="${femur_iyy}" iyz = "${femur_iyz}"
        izz="${femur_izz}" ixz="${femur_ixz}" />
    </inertial>
  </link>

  <link name="tibia_2">
    <collision>
      <geometry>
        <mesh filename="package://spyndra_description/meshes/tibia.stl" scale="0.001 0.001 0.001"/>
      </geometry>
      <material name="white"/>
      <origin xyz="${off_tx} ${off_ty} ${off_tz}" rpy="${pi/2} 0 ${-pi/2}"/>
    </collision>
    <visual>
      <geometry>
        <mesh filename="package://spyndra_description/meshes/tibia.stl" scale="0.001 0.001 0.001"/>
      </geometry>
      <material name="white"/>
      <origin xyz="${off_tx} ${off_ty} ${off_tz}" rpy="${pi/2} 0 ${-pi/2}"/>
    </visual>
    <inertial>
      <origin xyz="${tibia_origin_x} 0 0" rpy="0 0 0"/>
      <mass value="${mt}"/>
      <inertia ixx="${tibia_ixx}" ixy="${tibia_ixy}"
        iyy="${tibia_iyy}" iyz = "${tibia_iyz}"
        izz="${tibia_izz}" ixz="${tibia_ixz}" />
    </inertial>
  </link>

  <link name="femur_3">
    <collision>
      <geometry>
        <mesh filename="package://spyndra_description/meshes/femur.stl" scale="0.001 0.001 0.001"/>
      </geometry>
      <material name="red"/>
      <origin xyz="${off_fx} ${off_fy} ${off_fz}" rpy="${pi} ${-pi/2} 0"/>
    </collision>
    <visual>
      <geometry>
        <mesh filename="package://spyndra_description/meshes/femur.stl" scale="0.001 0.001 0.001"/>
      </geometry>
      <material name="red"/>
      <origin xyz="${off_fx} ${off_fy} ${off_fz}" rpy="${pi} ${-pi/2} 0"/>
    </visual>
    <inertial>
      <origin xyz="${femur_origin_x} 0 ${femur_origin_z}"  rpy="0 0 0"/>
      <mass value="${mc}"/>
      <inertia ixx="${femur_ixx}" ixy="${femur_ixy}"
        iyy="${femur_iyy}" iyz = "${femur_iyz}"
        izz="${femur_izz}" ixz="${femur_ixz}" />
    </inertial>
  </link>

  <link name="tibia_3">
    <collision>
      <geometry>
        <mesh filename="package://spyndra_description/meshes/tibia.stl" scale="0.001 0.001 0.001"/>
      </geometry>
      <material name="white"/>
      <origin xyz="${off_tx} ${off_ty} ${off_tz}" rpy="${pi/2} 0 ${-pi/2}"/>
    </collision>
    <visual>
      <geometry>
        <mesh filename="package://spyndra_description/meshes/tibia.stl" scale="0.001 0.001 0.001"/>
      </geometry>
      <material name="white"/>
      <origin xyz="${off_tx} ${off_ty} ${off_tz}" rpy="${pi/2} 0 ${-pi/2}"/>
    </visual>
    <inertial>
      <origin xyz="${tibia_origin_x} 0 0" rpy="0 0 0"/>
      <mass value="${mt}"/>
      <inertia ixx="${tibia_ixx}" ixy="${tibia_ixy}"
        iyy="${tibia_iyy}" iyz = "${tibia_iyz}"
        izz="${tibia_izz}" ixz="${tibia_ixz}" />
    </inertial>
  </link>

  <link name="femur_4">
    <collision>
      <geometry>
        <mesh filename="package://spyndra_description/meshes/femur.stl" scale="0.001 0.001 0.001"/>
      </geometry>
      <material name="red"/>
      <origin xyz="${off_fx} ${off_fy} ${off_fz}" rpy="${pi} ${-pi/2} 0"/>
    </collision>
    <visual>
      <geometry>
        <mesh filename="package://spyndra_description/meshes/femur.stl" scale="0.001 0.001 0.001"/>
      </geometry>
      <material name="red"/>
      <origin xyz="${off_fx} ${off_fy} ${off_fz}" rpy="${pi} ${-pi/2} 0"/>
    </visual>
    <inertial>
      <origin xyz="${femur_origin_x} 0 ${femur_origin_z}"  rpy="0 0 0"/>
      <mass value="${mc}"/>
      <inertia ixx="${femur_ixx}" ixy="${femur_ixy}"
        iyy="${femur_iyy}" iyz = "${femur_iyz}"
        izz="${femur_izz}" ixz="${femur_ixz}" />
    </inertial>
  </link>

  <link name="tibia_4">
    <collision>
      <geometry>
        <mesh filename="package://spyndra_description/meshes/tibia.stl" scale="0.001 0.001 0.001"/>
      </geometry>
      <material name="white"/>
      <origin xyz="${off_tx} ${off_ty} ${off_tz}" rpy="${pi/2} 0 ${-pi/2}"/>
    </collision>
    <visual>
      <geometry>
        <mesh filename="package://spyndra_description/meshes/tibia.stl" scale="0.001 0.001 0.001"/>
      </geometry>
      <material name="white"/>
      <origin xyz="${off_tx} ${off_ty} ${off_tz}" rpy="${pi/2} 0 ${-pi/2}"/>
    </visual>
    <inertial>
      <origin xyz="${tibia_origin_x} 0 0" rpy="0 0 0"/>
      <mass value="${mt}"/>
      <inertia ixx="${tibia_ixx}" ixy="${tibia_ixy}"
        iyy="${tibia_iyy}" iyz = "${tibia_iyz}"
        izz="${tibia_izz}" ixz="${tibia_ixz}" />
    </inertial>
  </link>

  <joint name="motor_f1" type="revolute">
    <parent link="base_link"/>
    <child link="femur_1"/>
    <axis xyz="0 1 0"/>
    <origin rpy="0 0 0" xyz="${jt_cx} ${jt_cy} ${jt_cz}"/>
    <limit effort="1000.0" lower="-0.5" upper="0.8" velocity="0.5"/>
  </joint>

  <joint name="motor_t1" type="revolute">
    <parent link="femur_1"/>
    <child link="tibia_1"/>
    <axis xyz="0 1 0"/>
    <origin rpy="0 0 0" xyz="${jt_fx} ${jt_fy} ${jt_fz}"/>
    <limit effort="1000.0" lower="-0.5" upper="0.8" velocity="0.5"/>
  </joint>

  <joint name="motor_f2" type="revolute">
    <parent link="base_link"/>
    <child link="femur_2"/>
    <axis xyz="0 1 0"/>
    <origin rpy="0 0 ${-pi/2}" xyz="${jt_cy} ${-jt_cx} ${jt_cz}"/>
    <limit effort="1000.0" lower="-0.5" upper="0.8" velocity="0.5"/>
  </joint>

  <joint name="motor_t2" type="revolute">
    <parent link="femur_2"/>
    <child link="tibia_2"/>
    <axis xyz="0 1 0"/>
    <origin rpy="0 0 0" xyz="${jt_fx} ${jt_fy} ${jt_fz}"/>
    <limit effort="1000.0" lower="-0.5" upper="0.8" velocity="0.5"/>
  </joint>

  <joint name="motor_f3" type="revolute">
    <parent link="base_link"/>
    <child link="femur_3"/>
    <axis xyz="0 1 0"/>
    <origin rpy="0 0 ${-pi}" xyz="${-jt_cx} ${-jt_cy} ${jt_cz}"/>
    <limit effort="1000.0" lower="-0.5" upper="0.8" velocity="0.5"/>
  </joint>

  <joint name="motor_t3" type="revolute">
    <parent link="femur_3"/>
    <child link="tibia_3"/>
    <axis xyz="0 1 0"/>
    <origin rpy="0 0 0" xyz="${jt_fx} ${jt_fy} ${jt_fz}"/>
    <limit effort="1000.0" lower="-0.5" upper="0.8" velocity="0.5"/>
  </joint>

  <joint name="motor_f4" type="revolute">
    <parent link="base_link"/>
    <child link="femur_4"/>
    <axis xyz="0 1 0"/>
    <origin rpy="0 0 ${pi/2}" xyz="${-jt_cy} ${jt_cx} ${jt_cz}"/>
    <limit effort="1000.0" lower="-0.5" upper="0.8" velocity="0.5"/>
  </joint>

  <joint name="motor_t4" type="revolute">
    <parent link="femur_4"/>
    <child link="tibia_4"/>
    <axis xyz="0 1 0"/>
    <origin rpy="0 0 0" xyz="${jt_fx} ${jt_fy} ${jt_fz}"/>
    <limit effort="1000.0" lower="-0.5" upper="0.8" velocity="0.5"/>
  </joint>

  <!-- Actuators -->
  <transmission name="tran_f1">
    <type>transmission_interface/SimpleTransmission</type>
    <joint name="motor_f1">
      <!--hardwareInterface>EffortJointInterface</hardwareInterface-->
      <hardwareInterface>EffortJointInterface</hardwareInterface>
    </joint>
    <actuator name="servo_f1">
      <hardwareInterface>EffortJointInterface</hardwareInterface>
      <mechanicalReduction>1</mechanicalReduction>
    </actuator>
  </transmission>

  <transmission name="tran_t1">
    <type>transmission_interface/SimpleTransmission</type>
    <joint name="motor_t1">
      <hardwareInterface>EffortJointInterface</hardwareInterface>
    </joint>
    <actuator name="servo_t1">
      <hardwareInterface>EffortJointInterface</hardwareInterface>
      <mechanicalReduction>1</mechanicalReduction>
    </actuator>
  </transmission>

  <transmission name="tran_f2">
    <type>transmission_interface/SimpleTransmission</type>
    <joint name="motor_f2">
      <hardwareInterface>EffortJointInterface</hardwareInterface>
    </joint>
    <actuator name="servo_f2">
      <hardwareInterface>EffortJointInterface</hardwareInterface>
      <mechanicalReduction>1</mechanicalReduction>
    </actuator>
  </transmission>

  <transmission name="tran_t2">
    <type>transmission_interface/SimpleTransmission</type>
    <joint name="motor_t2">
      <hardwareInterface>EffortJointInterface</hardwareInterface>
    </joint>
    <actuator name="servo_t2">
      <hardwareInterface>EffortJointInterface</hardwareInterface>
      <mechanicalReduction>1</mechanicalReduction>
    </actuator>
  </transmission>

  <transmission name="tran_f3">
    <type>transmission_interface/SimpleTransmission</type>
    <joint name="motor_f3">
      <hardwareInterface>EffortJointInterface</hardwareInterface>
    </joint>
    <actuator name="servo_f3">
      <hardwareInterface>EffortJointInterface</hardwareInterface>
      <mechanicalReduction>1</mechanicalReduction>
    </actuator>
  </transmission>

  <transmission name="tran_t3">
    <type>transmission_interface/SimpleTransmission</type>
    <joint name="motor_t3">
      <hardwareInterface>EffortJointInterface</hardwareInterface>
    </joint>
    <actuator name="servo_t3">
      <hardwareInterface>EffortJointInterface</hardwareInterface>
      <mechanicalReduction>1</mechanicalReduction>
    </actuator>
  </transmission>

  <transmission name="tran_f4">
    <type>transmission_interface/SimpleTransmission</type>
    <joint name="motor_f4">
      <hardwareInterface>EffortJointInterface</hardwareInterface>
    </joint>
    <actuator name="servo_f4">
      <hardwareInterface>EffortJointInterface</hardwareInterface>
      <mechanicalReduction>1</mechanicalReduction>
    </actuator>
  </transmission>

  <transmission name="tran_t4">
    <type>transmission_interface/SimpleTransmission</type>
    <joint name="motor_t4">
      <hardwareInterface>EffortJointInterface</hardwareInterface>
    </joint>
    <actuator name="servo_t4">
      <hardwareInterface>EffortJointInterface</hardwareInterface>
      <mechanicalReduction>1</mechanicalReduction>
    </actuator>
  </transmission>

</robot>
